Workbook

Sheet Как читать
A1: Полная статистика публикаций канала «Валентина Хлистун | Этикет»
A3: Источник данных | B3: Дзен-студия → Статистика → Публикации → «Отчёт», период «Всё время». Выгружено 25 июля 2026 года.
A4: Что внутри | B4: 1660 публикаций: 623 статьи, 661 ролик, 369 постов, 7 видео. Даты публикации — с февраля 2023 по 24 июля 2026.
A6: Показы | B6: Сколько раз карточка публикации попала людям в ленту. Это решение алгоритма, а не заслуга текста.
A7: Открытия | B7: Сколько раз публикацию открыли. В публичной карточке канала это же число показано как «просмотры».
A8: Дочитывания | B8: Сколько человек долистали до конца.
A9: CTR = открытия / показы | B9: Первая ступень воронки. За неё отвечают обложка, заголовок и тема — то, что видно в ленте.
A10: Дочитываемость = дочитывания / открытия | B10: Вторая ступень. За неё отвечает сам текст: первый экран, длина, ритм, структура.
A11: Лайки, комментарии, подписки на дочитывание | B11: Третья ступень: реакция тех, кто действительно прочитал.
A12: Индекс к периоду | B12: Показатель статьи, делённый на медиану всех публикаций того же типа за ±90 дней. 1,00 — как обычно в те месяцы; 2,00 — вдвое лучше обычного; 0,50 — вдвое хуже. Нужен потому, что канал рос и Дзен менял алгоритм: сравнивать статью 2023 года со статьёй 2026 года напрямую нельзя.
A14: Как этим НЕ пользоваться | B14: Абсолютные просмотры и лайки не показывают качество статьи: чем больше алгоритм дал показов, тем больше будет и то и другое. Сравнивать статьи между собой можно только по долям и индексам.
A15: Разные типы — разные вселенные | B15: У роликов медианный CTR около 30%, у статей — около 5%. В одну таблицу сравнения их сводить нельзя, поэтому они на разных листах.
A16: Свежие публикации | B16: Публикации моложе 30 дней ещё не набрали хвост показов. Их показатели занижены и в сравнения не идут.
A17: Что дальше | B17: Тексты статей размечаются по справочнику критериев ОТДЕЛЬНО и ВСЛЕПУЮ — без доступа к этим цифрам. Только потом разметка соединяется со статистикой. Иначе разбор подгонит признаки под уже известный результат.

Sheet Сводка
A1: Сводка: типичные значения (медианы)
A2: Медиана, а не среднее: одна вирусная публикация искажает среднее до бессмыслицы.
A4: Группа | B4: Публикаций | C4: Показы | D4: Открытия | E4: Дочитывания | F4: CTR | G4: Дочитываемость | H4: Мин. на дочитывание | I4: Лайки/дочит. | J4: Комм./дочит. | K4: Подписки/дочит.
A5: Статьи — все | B5: =COUNT(Статьи!$F$5:$F$627) -> 623 | C5: =IFERROR(MEDIAN(Статьи!$F$5:$F$627),"") -> 140440 | D5: =IFERROR(MEDIAN(Статьи!$G$5:$G$627),"") -> 10787 | E5: =IFERROR(MEDIAN(Статьи!$H$5:$H$627),"") -> 5339 | F5: =IFERROR(MEDIAN(Статьи!$M$5:$M$627),"") -> 0.054442563 | G5: =IFERROR(MEDIAN(Статьи!$N$5:$N$627),"") -> 0.53613516 | H5: =IFERROR(MEDIAN(Статьи!$O$5:$O$627),"") -> 0.97320146 | I5: =IFERROR(MEDIAN(Статьи!$P$5:$P$627),"") -> 0.055204512 | J5: =IFERROR(MEDIAN(Статьи!$Q$5:$Q$627),"") -> 0.010179645 | K5: =IFERROR(MEDIAN(Статьи!$R$5:$R$627),"") -> 0.0040031383
A6: Ролики — все | B6: =COUNT(Ролики!$F$5:$F$665) -> 661 | C6: =IFERROR(MEDIAN(Ролики!$F$5:$F$665),"") -> 46418 | D6: =IFERROR(MEDIAN(Ролики!$G$5:$G$665),"") -> 14153 | E6: =IFERROR(MEDIAN(Ролики!$H$5:$H$665),"") -> 12724 | F6: =IFERROR(MEDIAN(Ролики!$M$5:$M$665),"") -> 0.2970281 | G6: =IFERROR(MEDIAN(Ролики!$N$5:$N$665),"") -> 0.99991357 | H6: =IFERROR(MEDIAN(Ролики!$O$5:$O$665),"") -> 0.0040548767 | I6: =IFERROR(MEDIAN(Ролики!$P$5:$P$665),"") -> 0.012606504 | J6: =IFERROR(MEDIAN(Ролики!$Q$5:$Q$665),"") -> 0.00067249617 | K6: =IFERROR(MEDIAN(Ролики!$R$5:$R$665),"") -> 0.00068729663
A7: Посты — все | B7: =COUNT(Посты!$F$5:$F$373) -> 369 | C7: =IFERROR(MEDIAN(Посты!$F$5:$F$373),"") -> 3102 | D7: =IFERROR(MEDIAN(Посты!$G$5:$G$373),"") -> 222 | E7: =IFERROR(MEDIAN(Посты!$H$5:$H$373),"") -> 233 | F7: =IFERROR(MEDIAN(Посты!$M$5:$M$373),"") -> 0.069631031 | G7: =IFERROR(MEDIAN(Посты!$N$5:$N$373),"") -> 0.99646643 | H7: =IFERROR(MEDIAN(Посты!$O$5:$O$373),"") -> 0.54411765 | I7: =IFERROR(MEDIAN(Посты!$P$5:$P$373),"") -> 0.13366337 | J7: =IFERROR(MEDIAN(Посты!$Q$5:$Q$373),"") -> 0.020134228 | K7: =IFERROR(MEDIAN(Посты!$R$5:$R$373),"") -> 0
A8: Статьи — 2023 | B8: =COUNT(Статьи!$F$5:$F$56) -> 52 | C8: =IFERROR(MEDIAN(Статьи!$F$5:$F$56),"") -> 74706.5 | D8: =IFERROR(MEDIAN(Статьи!$G$5:$G$56),"") -> 3369.5 | E8: =IFERROR(MEDIAN(Статьи!$H$5:$H$56),"") -> 1915 | F8: =IFERROR(MEDIAN(Статьи!$M$5:$M$56),"") -> 0.040272355 | G8: =IFERROR(MEDIAN(Статьи!$N$5:$N$56),"") -> 0.5862069 | H8: =IFERROR(MEDIAN(Статьи!$O$5:$O$56),"") -> 0.96940727 | I8: =IFERROR(MEDIAN(Статьи!$P$5:$P$56),"") -> 0.0535815 | J8: =IFERROR(MEDIAN(Статьи!$Q$5:$Q$56),"") -> 0.0062215478 | K8: =IFERROR(MEDIAN(Статьи!$R$5:$R$56),"") -> 0.0062674874
A9: Статьи — 2024 | B9: =COUNT(Статьи!$F$57:$F$225) -> 169 | C9: =IFERROR(MEDIAN(Статьи!$F$57:$F$225),"") -> 166341 | D9: =IFERROR(MEDIAN(Статьи!$G$57:$G$225),"") -> 11208 | E9: =IFERROR(MEDIAN(Статьи!$H$57:$H$225),"") -> 6076 | F9: =IFERROR(MEDIAN(Статьи!$M$57:$M$225),"") -> 0.047701247 | G9: =IFERROR(MEDIAN(Статьи!$N$57:$N$225),"") -> 0.54700728 | H9: =IFERROR(MEDIAN(Статьи!$O$57:$O$225),"") -> 0.93809524 | I9: =IFERROR(MEDIAN(Статьи!$P$57:$P$225),"") -> 0.049435028 | J9: =IFERROR(MEDIAN(Статьи!$Q$57:$Q$225),"") -> 0.0098559515 | K9: =IFERROR(MEDIAN(Статьи!$R$57:$R$225),"") -> 0.0045026607
A10: Статьи — 2025 | B10: =COUNT(Статьи!$F$226:$F$465) -> 240 | C10: =IFERROR(MEDIAN(Статьи!$F$226:$F$465),"") -> 327575 | D10: =IFERROR(MEDIAN(Статьи!$G$226:$G$465),"") -> 25099 | E10: =IFERROR(MEDIAN(Статьи!$H$226:$H$465),"") -> 12304.5 | F10: =IFERROR(MEDIAN(Статьи!$M$226:$M$465),"") -> 0.063563112 | G10: =IFERROR(MEDIAN(Статьи!$N$226:$N$465),"") -> 0.53487649 | H10: =IFERROR(MEDIAN(Статьи!$O$226:$O$465),"") -> 1.0190826 | I10: =IFERROR(MEDIAN(Статьи!$P$226:$P$465),"") -> 0.048111912 | J10: =IFERROR(MEDIAN(Статьи!$Q$226:$Q$465),"") -> 0.00988042 | K10: =IFERROR(MEDIAN(Статьи!$R$226:$R$465),"") -> 0.0038535675
A11: Статьи — 2026 | B11: =COUNT(Статьи!$F$466:$F$627) -> 162 | C11: =IFERROR(MEDIAN(Статьи!$F$466:$F$627),"") -> 53200.5 | D11: =IFERROR(MEDIAN(Статьи!$G$466:$G$627),"") -> 2069.5 | E11: =IFERROR(MEDIAN(Статьи!$H$466:$H$627),"") -> 954.5 | F11: =IFERROR(MEDIAN(Статьи!$M$466:$M$627),"") -> 0.056578846 | G11: =IFERROR(MEDIAN(Статьи!$N$466:$N$627),"") -> 0.51848848 | H11: =IFERROR(MEDIAN(Статьи!$O$466:$O$627),"") -> 0.97133497 | I11: =IFERROR(MEDIAN(Статьи!$P$466:$P$627),"") -> 0.075450135 | J11: =IFERROR(MEDIAN(Статьи!$Q$466:$Q$627),"") -> 0.017843707 | K11: =IFERROR(MEDIAN(Статьи!$R$466:$R$627),"") -> 0.003732471
A13: Показатели рассчитаны по формулам от исходных чисел выгрузки — при обновлении данных пересчитаются автоматически.

Sheet Статьи
A1: Статьи
A2: Все статьи канала. Индексы считаются внутри этого листа — статья сравнивается только с другими статьями того же периода.
A4: Дата публикации | B4: Час | C4: День недели | D4: Заголовок | E4: Ссылка | F4: Показы | G4: Открытия | H4: Дочитывания | I4: Время просмотра, мин | J4: Лайки | K4: Комментарии | L4: Подписки | M4: CTR (открытия/показы) | N4: Дочитываемость | O4: Минут на дочитывание | P4: Лайки / дочитывания | Q4: Комментарии / дочитывания | R4: Подписки / дочитывания | S4: Индекс CTR к периоду | T4: Индекс дочитываемости к периоду | U4: Индекс комментариев к периоду
A5: 45013.501 | B5: 12 | C5: вт | D5: Моя удачная борьба со стрессом | E5: ссылка | F5: 10922 | G5: 215 | H5: 154 | I5: 10 | J5: 25 | K5: 2 | L5: 1 | M5: =IFERROR(G5/F5,"") -> 0.019685039 | N5: =IFERROR(H5/G5,"") -> 0.71627907 | O5: =IFERROR(I5/H5,"") -> 0.064935065 | P5: =IFERROR(J5/H5,"") -> 0.16233766 | Q5: =IFERROR(K5/H5,"") -> 0.012987013 | R5: =IFERROR(L5/H5,"") -> 0.0064935065 | S5: =IFERROR(M5/MEDIAN(INDEX($M$5:$M$627,MATCH($A5-90,$A$5:$A$627,1)):INDEX($M$5:$M$627,MATCH($A5+90,$A$5:$A$627,1))),"") | T5: =IFERROR(N5/MEDIAN(INDEX($N$5:$N$627,MATCH($A5-90,$A$5:$A$627,1)):INDEX($N$5:$N$627,MATCH($A5+90,$A$5:$A$627,1))),"") | U5: =IFERROR(Q5/MEDIAN(INDEX($Q$5:$Q$627,MATCH($A5-90,$A$5:$A$627,1)):INDEX($Q$5:$Q$627,MATCH($A5+90,$A$5:$A$627,1))),"")
A6: 45020.75 | B6: 17 | C6: вт | D6: Сервировка стола | E6: ссылка | F6: 371572 | G6: 22787 | H6: 13180 | I6: 7251 | J6: 1029 | K6: 82 | L6: 210 | M6: =IFERROR(G6/F6,"") -> 0.061325934 | N6: =IFERROR(H6/G6,"") -> 0.57839996 | O6: =IFERROR(I6/H6,"") -> 0.55015175 | P6: =IFERROR(J6/H6,"") -> 0.078072838 | Q6: =IFERROR(K6/H6,"") -> 0.0062215478 | R6: =IFERROR(L6/H6,"") -> 0.015933232 | S6: =IFERROR(M6/MEDIAN(INDEX($M$5:$M$627,MATCH($A6-90,$A$5:$A$627,1)):INDEX($M$5:$M$627,MATCH($A6+90,$A$5:$A$627,1))),"") | T6: =IFERROR(N6/MEDIAN(INDEX($N$5:$N$627,MATCH($A6-90,$A$5:$A$627,1)):INDEX($N$5:$N$627,MATCH($A6+90,$A$5:$A$627,1))),"") | U6: =IFERROR(Q6/MEDIAN(INDEX($Q$5:$Q$627,MATCH($A6-90,$A$5:$A$627,1)):INDEX($Q$5:$Q$627,MATCH($A6+90,$A$5:$A$627,1))),"")
A7: 45038.481 | B7: 11 | C7: сб | D7: Этот лайфхак столового этикета всегда в ваших руках | E7: ссылка | F7: 40126 | G7: 1754 | H7: 1205 | I7: 495 | J7: 183 | K7: 3 | L7: 13 | M7: =IFERROR(G7/F7,"") -> 0.043712306 | N7: =IFERROR(H7/G7,"") -> 0.68700114 | O7: =IFERROR(I7/H7,"") -> 0.41078838 | P7: =IFERROR(J7/H7,"") -> 0.15186722 | Q7: =IFERROR(K7/H7,"") -> 0.0024896266 | R7: =IFERROR(L7/H7,"") -> 0.010788382 | S7: =IFERROR(M7/MEDIAN(INDEX($M$5:$M$627,MATCH($A7-90,$A$5:$A$627,1)):INDEX($M$5:$M$627,MATCH($A7+90,$A$5:$A$627,1))),"") | T7: =IFERROR(N7/MEDIAN(INDEX($N$5:$N$627,MATCH($A7-90,$A$5:$A$627,1)):INDEX($N$5:$N$627,MATCH($A7+90,$A$5:$A$627,1))),"") | U7: =IFERROR(Q7/MEDIAN(INDEX($Q$5:$Q$627,MATCH($A7-90,$A$5:$A$627,1)):INDEX($Q$5:$Q$627,MATCH($A7+90,$A$5:$A$627,1))),"")
A8: 45073.723 | B8: 17 | C8: сб | D8: Формальный и неформальный деловой дресс-код | E8: ссылка | F8: 219296 | G8: 9471 | H8: 5271 | I8: 5471 | J8: 164 | K8: 15 | L8: 37 | M8: =IFERROR(G8/F8,"") -> 0.043188202 | N8: =IFERROR(H8/G8,"") -> 0.55654102 | O8: =IFERROR(I8/H8,"") -> 1.0379435 | P8: =IFERROR(J8/H8,"") -> 0.031113641 | Q8: =IFERROR(K8/H8,"") -> 0.0028457598 | R8: =IFERROR(L8/H8,"") -> 0.0070195409 | S8: =IFERROR(M8/MEDIAN(INDEX($M$5:$M$627,MATCH($A8-90,$A$5:$A$627,1)):INDEX($M$5:$M$627,MATCH($A8+90,$A$5:$A$627,1))),"") | T8: =IFERROR(N8/MEDIAN(INDEX($N$5:$N$627,MATCH($A8-90,$A$5:$A$627,1)):INDEX($N$5:$N$627,MATCH($A8+90,$A$5:$A$627,1))),"") | U8: =IFERROR(Q8/MEDIAN(INDEX($Q$5:$Q$627,MATCH($A8-90,$A$5:$A$627,1)):INDEX($Q$5:$Q$627,MATCH($A8+90,$A$5:$A$627,1))),"")
A9: 45147.664 | B9: 15 | C9: ср | D9: Этикет: ваш личный компас | E9: ссылка | F9: 12515 | G9: 451 | H9: 288 | I9: 315 | J9: 77 | K9: 3 | L9: 5 | M9: =IFERROR(G9/F9,"") -> 0.036036756 | N9: =IFERROR(H9/G9,"") -> 0.63858093 | O9: =IFERROR(I9/H9,"") -> 1.09375 | P9: =IFERROR(J9/H9,"") -> 0.26736111 | Q9: =IFERROR(K9/H9,"") -> 0.010416667 | R9: =IFERROR(L9/H9,"") -> 0.017361111 | S9: =IFERROR(M9/MEDIAN(INDEX($M$5:$M$627,MATCH($A9-90,$A$5:$A$627,1)):INDEX($M$5:$M$627,MATCH($A9+90,$A$5:$A$627,1))),"") -> 0.89327561 | T9: =IFERROR(N9/MEDIAN(INDEX($N$5:$N$627,MATCH($A9-90,$A$5:$A$627,1)):INDEX($N$5:$N$627,MATCH($A9+90,$A$5:$A$627,1))),"") -> 1.1946013 | U9: =IFERROR(Q9/MEDIAN(INDEX($Q$5:$Q$627,MATCH($A9-90,$A$5:$A$627,1)):INDEX($Q$5:$Q$627,MATCH($A9+90,$A$5:$A$627,1))),"") -> 3.6323973
A10: 45148.482 | B10: 11 | C10: чт | D10: Страх или безответственность? | E10: ссылка | F10: 199045 | G10: 11970 | H10: 5406 | I10: 6001 | J10: 281 | K10: 21 | L10: 33 | M10: =IFERROR(G10/F10,"") -> 0.060137155 | N10: =IFERROR(H10/G10,"") -> 0.45162907 | O10: =IFERROR(I10/H10,"") -> 1.1100629 | P10: =IFERROR(J10/H10,"") -> 0.051979282 | Q10: =IFERROR(K10/H10,"") -> 0.0038845727 | R10: =IFERROR(L10/H10,"") -> 0.0061043285 | S10: =IFERROR(M10/MEDIAN(INDEX($M$5:$M$627,MATCH($A10-90,$A$5:$A$627,1)):INDEX($M$5:$M$627,MATCH($A10+90,$A$5:$A$627,1))),"") -> 1.4938017 | T10: =IFERROR(N10/MEDIAN(INDEX($N$5:$N$627,MATCH($A10-90,$A$5:$A$627,1)):INDEX($N$5:$N$627,MATCH($A10+90,$A$5:$A$627,1))),"") -> 0.83720422 | U10: =IFERROR(Q10/MEDIAN(INDEX($Q$5:$Q$627,MATCH($A10-90,$A$5:$A$627,1)):INDEX($Q$5:$Q$627,MATCH($A10+90,$A$5:$A$627,1))),"") -> 1.1505952
A11: 45154.57 | B11: 13 | C11: ср | D11: Управление стрессом на рабочем месте: практические советы | E11: ссылка | F11: 132789 | G11: 4838 | H11: 2057 | I11: 2047 | J11: 118 | K11: 5 | L11: 18 | M11: =IFERROR(G11/F11,"") -> 0.036433741 | N11: =IFERROR(H11/G11,"") -> 0.42517569 | O11: =IFERROR(I11/H11,"") -> 0.99513855 | P11: =IFERROR(J11/H11,"") -> 0.057365095 | Q11: =IFERROR(K11/H11,"") -> 0.0024307244 | R11: =IFERROR(L11/H11,"") -> 0.0087506077 | S11: =IFERROR(M11/MEDIAN(INDEX($M$5:$M$627,MATCH($A11-90,$A$5:$A$627,1)):INDEX($M$5:$M$627,MATCH($A11+90,$A$5:$A$627,1))),"") -> 0.90691389 | T11: =IFERROR(N11/MEDIAN(INDEX($N$5:$N$627,MATCH($A11-90,$A$5:$A$627,1)):INDEX($N$5:$N$627,MATCH($A11+90,$A$5:$A$627,1))),"") -> 0.78108119 | U11: =IFERROR(Q11/MEDIAN(INDEX($Q$5:$Q$627,MATCH($A11-90,$A$5:$A$627,1)):INDEX($Q$5:$Q$627,MATCH($A11+90,$A$5:$A$627,1))),"") -> 0.6257379
A12: 45157.538 | B12: 12 | C12: сб | D12: Этикет в музее: Путеводитель по уважительному взаимодействию с искусством | E12: ссылка | F12: 19075 | G12: 709 | H12: 379 | I12: 347 | J12: 98 | K12: 16 | L12: 4 | M12: =IFERROR(G12/F12,"") -> 0.037169069 | N12: =IFERROR(H12/G12,"") -> 0.53455571 | O12: =IFERROR(I12/H12,"") -> 0.91556728 | P12: =IFERROR(J12/H12,"") -> 0.2585752 | Q12: =IFERROR(K12/H12,"") -> 0.042216359 | R12: =IFERROR(L12/H12,"") -> 0.01055409 | S12: =IFERROR(M12/MEDIAN(INDEX($M$5:$M$627,MATCH($A12-90,$A$5:$A$627,1)):INDEX($M$5:$M$627,MATCH($A12+90,$A$5:$A$627,1))),"") -> 0.95791943 | T12: =IFERROR(N12/MEDIAN(INDEX($N$5:$N$627,MATCH($A12-90,$A$5:$A$627,1)):INDEX($N$5:$N$627,MATCH($A12+90,$A$5:$A$627,1))),"") -> 0.9909289 | U12: =IFERROR(Q12/MEDIAN(INDEX($Q$5:$Q$627,MATCH($A12-90,$A$5:$A$627,1)):INDEX($Q$5:$Q$627,MATCH($A12+90,$A$5:$A$627,1))),"") -> 10.661313
A13: 45209.697 | B13: 16 | C13: вт | D13: Шпаргалка: Как ответить на вакансию и произвести впечатление | E13: ссылка | F13: 279905 | G13: 11292 | H13: 4480 | I13: 6461 | J13: 122 | K13: 32 | L13: 83 | M13: =IFERROR(G13/F13,"") -> 0.040342259 | N13: =IFERROR(H13/G13,"") -> 0.39674106 | O13: =IFERROR(I13/H13,"") -> 1.4421875 | P13: =IFERROR(J13/H13,"") -> 0.027232143 | Q13: =IFERROR(K13/H13,"") -> 0.0071428571 | R13: =IFERROR(L13/H13,"") -> 0.018526786 | S13: =IFERROR(M13/MEDIAN(INDEX($M$5:$M$627,MATCH($A13-90,$A$5:$A$627,1)):INDEX($M$5:$M$627,MATCH($A13+90,$A$5:$A$627,1))),"") -> 1.002969 | T13: =IFERROR(N13/MEDIAN(INDEX($N$5:$N$627,MATCH($A13-90,$A$5:$A$627,1)):INDEX($N$5:$N$627,MATCH($A13+90,$A$5:$A$627,1))),"") -> 0.67518203 | U13: =IFERROR(Q13/MEDIAN(INDEX($Q$5:$Q$627,MATCH($A13-90,$A$5:$A$627,1)):INDEX($Q$5:$Q$627,MATCH($A13+90,$A$5:$A$627,1))),"") -> 1.1005197
A14: 45211.736 | B14: 17 | C14: чт | D14: Эмоциональное равновесие: как справляться с грубостью и сохранять спокойствие | E14: ссылка | F14: 761072 | G14: 21093 | H14: 8935 | I14: 5393 | J14: 334 | K14: 75 | L14: 56 | M14: =IFERROR(G14/F14,"") -> 0.027714855 | N14: =IFERROR(H14/G14,"") -> 0.42360025 | O14: =IFERROR(I14/H14,"") -> 0.60358142 | P14: =IFERROR(J14/H14,"") -> 0.037381086 | Q14: =IFERROR(K14/H14,"") -> 0.0083939564 | R14: =IFERROR(L14/H14,"") -> 0.0062674874 | S14: =IFERROR(M14/MEDIAN(INDEX($M$5:$M$627,MATCH($A14-90,$A$5:$A$627,1)):INDEX($M$5:$M$627,MATCH($A14+90,$A$5:$A$627,1))),"") -> 0.6881856 | T14: =IFERROR(N14/MEDIAN(INDEX($N$5:$N$627,MATCH($A14-90,$A$5:$A$627,1)):INDEX($N$5:$N$627,MATCH($A14+90,$A$5:$A$627,1))),"") -> 0.71917909 | U14: =IFERROR(Q14/MEDIAN(INDEX($Q$5:$Q$627,MATCH($A14-90,$A$5:$A$627,1)):INDEX($Q$5:$Q$627,MATCH($A14+90,$A$5:$A$627,1))),"") -> 1.3085889
A15: 45213.827 | B15: 19 | C15: сб | D15: Как правильно сидеть даме по этикету: 3 лучших варианта | E15: ссылка | F15: 1359452 | G15: 91932 | H15: 68014 | I15: 47005 | J15: 2202 | K15: 150 | L15: 243 | M15: =IFERROR(G15/F15,"") -> 0.067624307 | N15: =IFERROR(H15/G15,"") -> 0.73982944 | O15: =IFERROR(I15/H15,"") -> 0.69110771 | P15: =IFERROR(J15/H15,"") -> 0.032375687 | Q15: =IFERROR(K15/H15,"") -> 0.0022054283 | R15: =IFERROR(L15/H15,"") -> 0.0035727938 | S15: =IFERROR(M15/MEDIAN(INDEX($M$5:$M$627,MATCH($A15-90,$A$5:$A$627,1)):INDEX($M$5:$M$627,MATCH($A15+90,$A$5:$A$627,1))),"") -> 1.6812416 | T15: =IFERROR(N15/MEDIAN(INDEX($N$5:$N$627,MATCH($A15-90,$A$5:$A$627,1)):INDEX($N$5:$N$627,MATCH($A15+90,$A$5:$A$627,1))),"") -> 1.2590568 | U15: =IFERROR(Q15/MEDIAN(INDEX($Q$5:$Q$627,MATCH($A15-90,$A$5:$A$627,1)):INDEX($Q$5:$Q$627,MATCH($A15+90,$A$5:$A$627,1))),"") -> 0.35286312
A16: 45215.858 | B16: 20 | C16: пн | D16: Этикет под зонтом | E16: ссылка | F16: 0 | G16: 0 | H16: 0 | I16: 4 | J16: 0 | K16: 0 | L16: 0 | M16: =IFERROR(G16/F16,"") | N16: =IFERROR(H16/G16,"") | O16: =IFERROR(I16/H16,"") | P16: =IFERROR(J16/H16,"") | Q16: =IFERROR(K16/H16,"") | R16: =IFERROR(L16/H16,"") | S16: =IFERROR(M16/MEDIAN(INDEX($M$5:$M$627,MATCH($A16-90,$A$5:$A$627,1)):INDEX($M$5:$M$627,MATCH($A16+90,$A$5:$A$627,1))),"") | T16: =IFERROR(N16/MEDIAN(INDEX($N$5:$N$627,MATCH($A16-90,$A$5:$A$627,1)):INDEX($N$5:$N$627,MATCH($A16+90,$A$5:$A$627,1))),"") | U16: =IFERROR(Q16/MEDIAN(INDEX($Q$5:$Q$627,MATCH($A16-90,$A$5:$A$627,1)):INDEX($Q$5:$Q$627,MATCH($A16+90,$A$5:$A$627,1))),"")
... A627: 46227.572 | B627: 13 | C627: пт | D627: Лицемерная помощь | E627: ссылка | F627: 4285 | G627: 746 | H627: 432 | I627: 0 | J627: 60 | K627: 234 | L627: 0 | M627: =IFERROR(G627/F627,"") -> 0.17409568 | N627: =IFERROR(H627/G627,"") -> 0.57908847 | O627: =IFERROR(I627/H627,"") -> 0 | P627: =IFERROR(J627/H627,"") -> 0.13888889 | Q627: =IFERROR(K627/H627,"") -> 0.54166667 | R627: =IFERROR(L627/H627,"") -> 0 | S627: =IFERROR(M627/MEDIAN(INDEX($M$5:$M$627,MATCH($A627-90,$A$5:$A$627,1)):INDEX($M$5:$M$627,MATCH($A627+90,$A$5:$A$627,1))),"") -> 2.4373396 | T627: =IFERROR(N627/MEDIAN(INDEX($N$5:$N$627,MATCH($A627-90,$A$5:$A$627,1)):INDEX($N$5:$N$627,MATCH($A627+90,$A$5:$A$627,1))),"") -> 1.1013148 | U627: =IFERROR(Q627/MEDIAN(INDEX($Q$5:$Q$627,MATCH($A627-90,$A$5:$A$627,1)):INDEX($Q$5:$Q$627,MATCH($A627+90,$A$5:$A$627,1))),"") -> 10.170398

Sheet Ролики
A1: Ролики
A2: Ролики. Отдельный лист: их воронка устроена иначе, сравнение со статьями некорректно.
A4: Дата публикации | B4: Час | C4: День недели | D4: Заголовок | E4: Ссылка | F4: Показы | G4: Открытия | H4: Дочитывания | I4: Время просмотра, мин | J4: Лайки | K4: Комментарии | L4: Подписки | M4: CTR (открытия/показы) | N4: Дочитываемость | O4: Минут на дочитывание | P4: Лайки / дочитывания | Q4: Комментарии / дочитывания | R4: Подписки / дочитывания | S4: Индекс CTR к периоду | T4: Индекс дочитываемости к периоду | U4: Индекс комментариев к периоду
A5: 44960.839 | B5: 20 | C5: пт | D5: Проверьте свои знания в этикете 🙌🏻 | E5: ссылка | F5: 23914 | G5: 12583 | H5: 12589 | I5: 25 | J5: 267 | K5: 13 | L5: 34 | M5: =IFERROR(G5/F5,"") -> 0.52617713 | N5: =IFERROR(H5/G5,"") -> 1.0004768 | O5: =IFERROR(I5/H5,"") -> 0.0019858607 | P5: =IFERROR(J5/H5,"") -> 0.021208992 | Q5: =IFERROR(K5/H5,"") -> 0.0010326475 | R5: =IFERROR(L5/H5,"") -> 0.0027007705 | S5: =IFERROR(M5/MEDIAN(INDEX($M$5:$M$665,MATCH($A5-90,$A$5:$A$665,1)):INDEX($M$5:$M$665,MATCH($A5+90,$A$5:$A$665,1))),"") | T5: =IFERROR(N5/MEDIAN(INDEX($N$5:$N$665,MATCH($A5-90,$A$5:$A$665,1)):INDEX($N$5:$N$665,MATCH($A5+90,$A$5:$A$665,1))),"") | U5: =IFERROR(Q5/MEDIAN(INDEX($Q$5:$Q$665,MATCH($A5-90,$A$5:$A$665,1)):INDEX($Q$5:$Q$665,MATCH($A5+90,$A$5:$A$665,1))),"")
A6: 44961.546 | B6: 13 | C6: сб | D6: Несколько правил столового этикета🍽 #этикет #этикетзастолом #столовыйэтикет #правилаэтикета | E6: ссылка | F6: 4422 | G6: 2420 | H6: 2427 | I6: 113 | J6: 152 | K6: 4 | L6: 2 | M6: =IFERROR(G6/F6,"") -> 0.54726368 | N6: =IFERROR(H6/G6,"") -> 1.0028926 | O6: =IFERROR(I6/H6,"") -> 0.046559539 | P6: =IFERROR(J6/H6,"") -> 0.06262876 | Q6: =IFERROR(K6/H6,"") -> 0.0016481253 | R6: =IFERROR(L6/H6,"") -> 0.00082406263 | S6: =IFERROR(M6/MEDIAN(INDEX($M$5:$M$665,MATCH($A6-90,$A$5:$A$665,1)):INDEX($M$5:$M$665,MATCH($A6+90,$A$5:$A$665,1))),"") | T6: =IFERROR(N6/MEDIAN(INDEX($N$5:$N$665,MATCH($A6-90,$A$5:$A$665,1)):INDEX($N$5:$N$665,MATCH($A6+90,$A$5:$A$665,1))),"") | U6: =IFERROR(Q6/MEDIAN(INDEX($Q$5:$Q$665,MATCH($A6-90,$A$5:$A$665,1)):INDEX($Q$5:$Q$665,MATCH($A6+90,$A$5:$A$665,1))),"")
A7: 44961.75 | B7: 18 | C7: сб | D7: НЕ деловая причёска ❌ #правилаэтикета #этикет #деловойстиль #деловойэтикет #деловойобраз #деловойимидж | E7: ссылка | F7: 4089 | G7: 2091 | H7: 2086 | I7: 10 | J7: 164 | K7: 5 | L7: 4 | M7: =IFERROR(G7/F7,"") -> 0.51137197 | N7: =IFERROR(H7/G7,"") -> 0.9976088 | O7: =IFERROR(I7/H7,"") -> 0.0047938639 | P7: =IFERROR(J7/H7,"") -> 0.078619367 | Q7: =IFERROR(K7/H7,"") -> 0.0023969319 | R7: =IFERROR(L7/H7,"") -> 0.0019175455 | S7: =IFERROR(M7/MEDIAN(INDEX($M$5:$M$665,MATCH($A7-90,$A$5:$A$665,1)):INDEX($M$5:$M$665,MATCH($A7+90,$A$5:$A$665,1))),"") | T7: =IFERROR(N7/MEDIAN(INDEX($N$5:$N$665,MATCH($A7-90,$A$5:$A$665,1)):INDEX($N$5:$N$665,MATCH($A7+90,$A$5:$A$665,1))),"") | U7: =IFERROR(Q7/MEDIAN(INDEX($Q$5:$Q$665,MATCH($A7-90,$A$5:$A$665,1)):INDEX($Q$5:$Q$665,MATCH($A7+90,$A$5:$A$665,1))),"")
A8: 44962.5 | B8: 12 | C8: вс | D8: Несколько помад, которые вас никогда не подведут #помада #помададлягуб #губнаяпомада #этикет #деловойстиль #деловойимидж | E8: ссылка | F8: 2525 | G8: 1497 | H8: 1499 | I8: 9 | J8: 114 | K8: 3 | L8: 2 | M8: =IFERROR(G8/F8,"") -> 0.59287129 | N8: =IFERROR(H8/G8,"") -> 1.001336 | O8: =IFERROR(I8/H8,"") -> 0.0060040027 | P8: =IFERROR(J8/H8,"") -> 0.0760507 | Q8: =IFERROR(K8/H8,"") -> 0.0020013342 | R8: =IFERROR(L8/H8,"") -> 0.0013342228 | S8: =IFERROR(M8/MEDIAN(INDEX($M$5:$M$665,MATCH($A8-90,$A$5:$A$665,1)):INDEX($M$5:$M$665,MATCH($A8+90,$A$5:$A$665,1))),"") | T8: =IFERROR(N8/MEDIAN(INDEX($N$5:$N$665,MATCH($A8-90,$A$5:$A$665,1)):INDEX($N$5:$N$665,MATCH($A8+90,$A$5:$A$665,1))),"") | U8: =IFERROR(Q8/MEDIAN(INDEX($Q$5:$Q$665,MATCH($A8-90,$A$5:$A$665,1)):INDEX($Q$5:$Q$665,MATCH($A8+90,$A$5:$A$665,1))),"")
A9: 44962.75 | B9: 17 | C9: вс | D9: Какие оттенки помад допустимы в деловом образе? #этикет #деловойстиль #деловойэтикет #деловойобраз #деловойимидж #помада #помададлягуб #губнаяпомада | E9: ссылка | F9: 21490 | G9: 7048 | H9: 7046 | I9: 5 | J9: 139 | K9: 4 | L9: 13 | M9: =IFERROR(G9/F9,"") -> 0.3279665 | N9: =IFERROR(H9/G9,"") -> 0.99971623 | O9: =IFERROR(I9/H9,"") -> 0.00070962248 | P9: =IFERROR(J9/H9,"") -> 0.019727505 | Q9: =IFERROR(K9/H9,"") -> 0.00056769798 | R9: =IFERROR(L9/H9,"") -> 0.0018450185 | S9: =IFERROR(M9/MEDIAN(INDEX($M$5:$M$665,MATCH($A9-90,$A$5:$A$665,1)):INDEX($M$5:$M$665,MATCH($A9+90,$A$5:$A$665,1))),"") | T9: =IFERROR(N9/MEDIAN(INDEX($N$5:$N$665,MATCH($A9-90,$A$5:$A$665,1)):INDEX($N$5:$N$665,MATCH($A9+90,$A$5:$A$665,1))),"") | U9: =IFERROR(Q9/MEDIAN(INDEX($Q$5:$Q$665,MATCH($A9-90,$A$5:$A$665,1)):INDEX($Q$5:$Q$665,MATCH($A9+90,$A$5:$A$665,1))),"")
A10: 44963.5 | B10: 11 | C10: пн | D10: Проверьте свои знания в этикете 🙌🏻 #деловойстиль #этикет #деловойимидж #правилаэтикета #деловойэтикет #деловойобраз #приветствие | E10: ссылка | F10: 28486 | G10: 12811 | H10: 12814 | I10: 10 | J10: 191 | K10: 13 | L10: 9 | M10: =IFERROR(G10/F10,"") -> 0.44972969 | N10: =IFERROR(H10/G10,"") -> 1.0002342 | O10: =IFERROR(I10/H10,"") -> 0.00078039644 | P10: =IFERROR(J10/H10,"") -> 0.014905572 | Q10: =IFERROR(K10/H10,"") -> 0.0010145154 | R10: =IFERROR(L10/H10,"") -> 0.0007023568 | S10: =IFERROR(M10/MEDIAN(INDEX($M$5:$M$665,MATCH($A10-90,$A$5:$A$665,1)):INDEX($M$5:$M$665,MATCH($A10+90,$A$5:$A$665,1))),"") | T10: =IFERROR(N10/MEDIAN(INDEX($N$5:$N$665,MATCH($A10-90,$A$5:$A$665,1)):INDEX($N$5:$N$665,MATCH($A10+90,$A$5:$A$665,1))),"") | U10: =IFERROR(Q10/MEDIAN(INDEX($Q$5:$Q$665,MATCH($A10-90,$A$5:$A$665,1)):INDEX($Q$5:$Q$665,MATCH($A10+90,$A$5:$A$665,1))),"")
A11: 44964.616 | B11: 14 | C11: вт | D11: Почему этикет не любит слово здравствуйте? #этикет #деловойстиль #деловойимидж #правилаэтикета #деловойобраз #приветствие | E11: ссылка | F11: 29810 | G11: 18272 | H11: 18271 | I11: 5 | J11: 201 | K11: 31 | L11: 89 | M11: =IFERROR(G11/F11,"") -> 0.61294867 | N11: =IFERROR(H11/G11,"") -> 0.99994527 | O11: =IFERROR(I11/H11,"") -> 0.00027365771 | P11: =IFERROR(J11/H11,"") -> 0.01100104 | Q11: =IFERROR(K11/H11,"") -> 0.0016966778 | R11: =IFERROR(L11/H11,"") -> 0.0048711072 | S11: =IFERROR(M11/MEDIAN(INDEX($M$5:$M$665,MATCH($A11-90,$A$5:$A$665,1)):INDEX($M$5:$M$665,MATCH($A11+90,$A$5:$A$665,1))),"") | T11: =IFERROR(N11/MEDIAN(INDEX($N$5:$N$665,MATCH($A11-90,$A$5:$A$665,1)):INDEX($N$5:$N$665,MATCH($A11+90,$A$5:$A$665,1))),"") | U11: =IFERROR(Q11/MEDIAN(INDEX($Q$5:$Q$665,MATCH($A11-90,$A$5:$A$665,1)):INDEX($Q$5:$Q$665,MATCH($A11+90,$A$5:$A$665,1))),"")
A12: 44964.666 | B12: 15 | C12: вт | D12: Как правильно здороваться? #этикет #деловойстиль #деловоеобщение #этикетобщения #деловыепереговоры #деловаярепутация | E12: ссылка | F12: 60880 | G12: 26764 | H12: 26762 | I12: 4 | J12: 284 | K12: 35 | L12: 55 | M12: =IFERROR(G12/F12,"") -> 0.43961892 | N12: =IFERROR(H12/G12,"") -> 0.99992527 | O12: =IFERROR(I12/H12,"") -> 0.00014946566 | P12: =IFERROR(J12/H12,"") -> 0.010612062 | Q12: =IFERROR(K12/H12,"") -> 0.0013078245 | R12: =IFERROR(L12/H12,"") -> 0.0020551528 | S12: =IFERROR(M12/MEDIAN(INDEX($M$5:$M$665,MATCH($A12-90,$A$5:$A$665,1)):INDEX($M$5:$M$665,MATCH($A12+90,$A$5:$A$665,1))),"") | T12: =IFERROR(N12/MEDIAN(INDEX($N$5:$N$665,MATCH($A12-90,$A$5:$A$665,1)):INDEX($N$5:$N$665,MATCH($A12+90,$A$5:$A$665,1))),"") | U12: =IFERROR(Q12/MEDIAN(INDEX($Q$5:$Q$665,MATCH($A12-90,$A$5:$A$665,1)):INDEX($Q$5:$Q$665,MATCH($A12+90,$A$5:$A$665,1))),"")
A13: 44965.424 | B13: 10 | C13: ср | D13: Нежелательные звонки #этикет #деловойстиль #деловойимидж #правилаэтикета #деловойэтикет #этикетобщения #деловыепереговоры #звонокпотелефону | E13: ссылка | F13: 4523 | G13: 2419 | H13: 2414 | I13: 29 | J13: 113 | K13: 8 | L13: 2 | M13: =IFERROR(G13/F13,"") -> 0.53482202 | N13: =IFERROR(H13/G13,"") -> 0.99793303 | O13: =IFERROR(I13/H13,"") -> 0.012013256 | P13: =IFERROR(J13/H13,"") -> 0.046810273 | Q13: =IFERROR(K13/H13,"") -> 0.0033140017 | R13: =IFERROR(L13/H13,"") -> 0.00082850041 | S13: =IFERROR(M13/MEDIAN(INDEX($M$5:$M$665,MATCH($A13-90,$A$5:$A$665,1)):INDEX($M$5:$M$665,MATCH($A13+90,$A$5:$A$665,1))),"") | T13: =IFERROR(N13/MEDIAN(INDEX($N$5:$N$665,MATCH($A13-90,$A$5:$A$665,1)):INDEX($N$5:$N$665,MATCH($A13+90,$A$5:$A$665,1))),"") | U13: =IFERROR(Q13/MEDIAN(INDEX($Q$5:$Q$665,MATCH($A13-90,$A$5:$A$665,1)):INDEX($Q$5:$Q$665,MATCH($A13+90,$A$5:$A$665,1))),"")
A14: 44965.584 | B14: 14 | C14: ср | D14: Наша речь - отражение нас самих #этикет #деловойстиль #деловойимидж #правилаэтикета #деловойобраз #деловойэтикет #деловыепереговоры #деловаярепутация #этикетобщения #правильнаяречь #грамотнаяречь | E14: ссылка | F14: 1909 | G14: 1168 | H14: 1147 | I14: 9 | J14: 91 | K14: 7 | L14: 13 | M14: =IFERROR(G14/F14,"") -> 0.61183866 | N14: =IFERROR(H14/G14,"") -> 0.98202055 | O14: =IFERROR(I14/H14,"") -> 0.0078465562 | P14: =IFERROR(J14/H14,"") -> 0.079337402 | Q14: =IFERROR(K14/H14,"") -> 0.0061028771 | R14: =IFERROR(L14/H14,"") -> 0.011333915 | S14: =IFERROR(M14/MEDIAN(INDEX($M$5:$M$665,MATCH($A14-90,$A$5:$A$665,1)):INDEX($M$5:$M$665,MATCH($A14+90,$A$5:$A$665,1))),"") | T14: =IFERROR(N14/MEDIAN(INDEX($N$5:$N$665,MATCH($A14-90,$A$5:$A$665,1)):INDEX($N$5:$N$665,MATCH($A14+90,$A$5:$A$665,1))),"") | U14: =IFERROR(Q14/MEDIAN(INDEX($Q$5:$Q$665,MATCH($A14-90,$A$5:$A$665,1)):INDEX($Q$5:$Q$665,MATCH($A14+90,$A$5:$A$665,1))),"")
A15: 44965.667 | B15: 15 | C15: ср | D15: Умение слушать 👂🏻 #этикет #этикетобщения #правилаэтикета #деловойэтикет #деловоеобщение #деловыекоммуникации #деловыеотношения #деловыепереговоры | E15: ссылка | F15: 6329 | G15: 2980 | H15: 2978 | I15: 7 | J15: 110 | K15: 2 | L15: 7 | M15: =IFERROR(G15/F15,"") -> 0.47084848 | N15: =IFERROR(H15/G15,"") -> 0.99932886 | O15: =IFERROR(I15/H15,"") -> 0.0023505709 | P15: =IFERROR(J15/H15,"") -> 0.036937542 | Q15: =IFERROR(K15/H15,"") -> 0.00067159167 | R15: =IFERROR(L15/H15,"") -> 0.0023505709 | S15: =IFERROR(M15/MEDIAN(INDEX($M$5:$M$665,MATCH($A15-90,$A$5:$A$665,1)):INDEX($M$5:$M$665,MATCH($A15+90,$A$5:$A$665,1))),"") | T15: =IFERROR(N15/MEDIAN(INDEX($N$5:$N$665,MATCH($A15-90,$A$5:$A$665,1)):INDEX($N$5:$N$665,MATCH($A15+90,$A$5:$A$665,1))),"") | U15: =IFERROR(Q15/MEDIAN(INDEX($Q$5:$Q$665,MATCH($A15-90,$A$5:$A$665,1)):INDEX($Q$5:$Q$665,MATCH($A15+90,$A$5:$A$665,1))),"")
A16: 44965.75 | B16: 17 | C16: ср | D16: Слова "паразиты" #грамотнаяречь #правильнаяречь #красиваяречь #правилаэтикета #этикет #деловыепереговоры #деловыеотношения #деловойэтикет #деловойимидж | E16: ссылка | F16: 9857 | G16: 4488 | H16: 4486 | I16: 8 | J16: 180 | K16: 11 | L16: 20 | M16: =IFERROR(G16/F16,"") -> 0.45531095 | N16: =IFERROR(H16/G16,"") -> 0.99955437 | O16: =IFERROR(I16/H16,"") -> 0.0017833259 | P16: =IFERROR(J16/H16,"") -> 0.040124833 | Q16: =IFERROR(K16/H16,"") -> 0.0024520731 | R16: =IFERROR(L16/H16,"") -> 0.0044583148 | S16: =IFERROR(M16/MEDIAN(INDEX($M$5:$M$665,MATCH($A16-90,$A$5:$A$665,1)):INDEX($M$5:$M$665,MATCH($A16+90,$A$5:$A$665,1))),"") | T16: =IFERROR(N16/MEDIAN(INDEX($N$5:$N$665,MATCH($A16-90,$A$5:$A$665,1)):INDEX($N$5:$N$665,MATCH($A16+90,$A$5:$A$665,1))),"") | U16: =IFERROR(Q16/MEDIAN(INDEX($Q$5:$Q$665,MATCH($A16-90,$A$5:$A$665,1)):INDEX($Q$5:$Q$665,MATCH($A16+90,$A$5:$A$665,1))),"")
... A109: 45035.583 | B109: 13 | C109: ср | D109: Уважаемые пешеходы! #правилаэтикета #этикет #деловоеобщение #деловойэтикет #деловаярепутация #общественныеместа #этикетобщения | E109: ссылка | F109: 117386 | G109: 22425 | H109: 22420 | I109: 5 | J109: 305 | K109: 29 | L109: 21 | M109: =IFERROR(G109/F109,"") -> 0.19103641 | N109: =IFERROR(H109/G109,"") -> 0.99977703 | O109: =IFERROR(I109/H109,"") -> 0.00022301517 | P109: =IFERROR(J109/H109,"") -> 0.013603925 | Q109: =IFERROR(K109/H109,"") -> 0.001293488 | R109: =IFERROR(L109/H109,"") -> 0.00093666369 | S109: =IFERROR(M109/MEDIAN(INDEX($M$5:$M$665,MATCH($A109-90,$A$5:$A$665,1)):INDEX($M$5:$M$665,MATCH($A109+90,$A$5:$A$665,1))),"") | T109: =IFERROR(N109/MEDIAN(INDEX($N$5:$N$665,MATCH($A109-90,$A$5:$A$665,1)):INDEX($N$5:$N$665,MATCH($A109+90,$A$5:$A$665,1))),"") | U109: =IFERROR(Q109/MEDIAN(INDEX($Q$5:$Q$665,MATCH($A109-90,$A$5:$A$665,1)):INDEX($Q$5:$Q$665,MATCH($A109+90,$A$5:$A$665,1))),"")
A110: 45036.263 | B110: 6 | C110: чт | E110: ссылка | F110: 78383 | G110: 15586 | H110: 15582 | I110: 3 | J110: 204 | K110: 24 | L110: 18 | M110: =IFERROR(G110/F110,"") -> 0.19884414 | N110: =IFERROR(H110/G110,"") -> 0.99974336 | O110: =IFERROR(I110/H110,"") -> 0.00019252984 | P110: =IFERROR(J110/H110,"") -> 0.013092029 | Q110: =IFERROR(K110/H110,"") -> 0.0015402387 | R110: =IFERROR(L110/H110,"") -> 0.0011551791 | S110: =IFERROR(M110/MEDIAN(INDEX($M$5:$M$665,MATCH($A110-90,$A$5:$A$665,1)):INDEX($M$5:$M$665,MATCH($A110+90,$A$5:$A$665,1))),"") | T110: =IFERROR(N110/MEDIAN(INDEX($N$5:$N$665,MATCH($A110-90,$A$5:$A$665,1)):INDEX($N$5:$N$665,MATCH($A110+90,$A$5:$A$665,1))),"") | U110: =IFERROR(Q110/MEDIAN(INDEX($Q$5:$Q$665,MATCH($A110-90,$A$5:$A$665,1)):INDEX($Q$5:$Q$665,MATCH($A110+90,$A$5:$A$665,1))),"")
A111: 45037.432 | B111: 10 | C111: пт | E111: ссылка | F111: 23834 | G111: 8221 | H111: 8218 | I111: 2 | J111: 304 | K111: 17 | L111: 11 | M111: =IFERROR(G111/F111,"") -> 0.34492741 | N111: =IFERROR(H111/G111,"") -> 0.99963508 | O111: =IFERROR(I111/H111,"") -> 0.00024336822 | P111: =IFERROR(J111/H111,"") -> 0.036991969 | Q111: =IFERROR(K111/H111,"") -> 0.0020686298 | R111: =IFERROR(L111/H111,"") -> 0.0013385252 | S111: =IFERROR(M111/MEDIAN(INDEX($M$5:$M$665,MATCH($A111-90,$A$5:$A$665,1)):INDEX($M$5:$M$665,MATCH($A111+90,$A$5:$A$665,1))),"") | T111: =IFERROR(N111/MEDIAN(INDEX($N$5:$N$665,MATCH($A111-90,$A$5:$A$665,1)):INDEX($N$5:$N$665,MATCH($A111+90,$A$5:$A$665,1))),"") | U111: =IFERROR(Q111/MEDIAN(INDEX($Q$5:$Q$665,MATCH($A111-90,$A$5:$A$665,1)):INDEX($Q$5:$Q$665,MATCH($A111+90,$A$5:$A$665,1))),"")
A112: 45038.714 | B112: 17 | C112: сб | D112: В лифте #правилаэтикета #этикет #лифт #общественныеместа #этикетобщения | E112: ссылка | F112: 89025 | G112: 15087 | H112: 15082 | I112: 3 | J112: 211 | K112: 10 | L112: 11 | M112: =IFERROR(G112/F112,"") -> 0.16946925 | N112: =IFERROR(H112/G112,"") -> 0.99966859 | O112: =IFERROR(I112/H112,"") -> 0.00019891261 | P112: =IFERROR(J112/H112,"") -> 0.013990187 | Q112: =IFERROR(K112/H112,"") -> 0.00066304204 | R112: =IFERROR(L112/H112,"") -> 0.00072934624 | S112: =IFERROR(M112/MEDIAN(INDEX($M$5:$M$665,MATCH($A112-90,$A$5:$A$665,1)):INDEX($M$5:$M$665,MATCH($A112+90,$A$5:$A$665,1))),"") | T112: =IFERROR(N112/MEDIAN(INDEX($N$5:$N$665,MATCH($A112-90,$A$5:$A$665,1)):INDEX($N$5:$N$665,MATCH($A112+90,$A$5:$A$665,1))),"") | U112: =IFERROR(Q112/MEDIAN(INDEX($Q$5:$Q$665,MATCH($A112-90,$A$5:$A$665,1)):INDEX($Q$5:$Q$665,MATCH($A112+90,$A$5:$A$665,1))),"")
A113: 45039.521 | B113: 12 | C113: вс | D113: Можно не знать этикет, но.. #правилаэтикета #этикет #деловоеобщение #деловойэтикет #деловаярепутация #деловыепереговоры #этикетобщения | E113: ссылка | F113: 210821 | G113: 35177 | H113: 35171 | I113: 6 | J113: 296 | K113: 20 | L113: 24 | M113: =IFERROR(G113/F113,"") -> 0.16685719 | N113: =IFERROR(H113/G113,"") -> 0.99982943 | O113: =IFERROR(I113/H113,"") -> 0.00017059509 | P113: =IFERROR(J113/H113,"") -> 0.0084160246 | Q113: =IFERROR(K113/H113,"") -> 0.00056865031 | R113: =IFERROR(L113/H113,"") -> 0.00068238037 | S113: =IFERROR(M113/MEDIAN(INDEX($M$5:$M$665,MATCH($A113-90,$A$5:$A$665,1)):INDEX($M$5:$M$665,MATCH($A113+90,$A$5:$A$665,1))),"") | T113: =IFERROR(N113/MEDIAN(INDEX($N$5:$N$665,MATCH($A113-90,$A$5:$A$665,1)):INDEX($N$5:$N$665,MATCH($A113+90,$A$5:$A$665,1))),"") | U113: =IFERROR(Q113/MEDIAN(INDEX($Q$5:$Q$665,MATCH($A113-90,$A$5:$A$665,1)):INDEX($Q$5:$Q$665,MATCH($A113+90,$A$5:$A$665,1))),"")
A114: 45040.583 | B114: 13 | C114: пн | D114: Не дарите цветы в горшках #правилаэтикета #этикет #деловоеобщение #деловойэтикет #деловаярепутация #подарки #цветы #деловыеотношения | E114: ссылка | F114: 199781 | G114: 40291 | H114: 40292 | I114: 31 | J114: 298 | K114: 13 | L114: 15 | M114: =IFERROR(G114/F114,"") -> 0.20167584 | N114: =IFERROR(H114/G114,"") -> 1.0000248 | O114: =IFERROR(I114/H114,"") -> 0.0007693835 | P114: =IFERROR(J114/H114,"") -> 0.0073960091 | Q114: =IFERROR(K114/H114,"") -> 0.00032264469 | R114: =IFERROR(L114/H114,"") -> 0.00037228234 | S114: =IFERROR(M114/MEDIAN(INDEX($M$5:$M$665,MATCH($A114-90,$A$5:$A$665,1)):INDEX($M$5:$M$665,MATCH($A114+90,$A$5:$A$665,1))),"") | T114: =IFERROR(N114/MEDIAN(INDEX($N$5:$N$665,MATCH($A114-90,$A$5:$A$665,1)):INDEX($N$5:$N$665,MATCH($A114+90,$A$5:$A$665,1))),"") | U114: =IFERROR(Q114/MEDIAN(INDEX($Q$5:$Q$665,MATCH($A114-90,$A$5:$A$665,1)):INDEX($Q$5:$Q$665,MATCH($A114+90,$A$5:$A$665,1))),"")
A115: 45041.5 | B115: 12 | C115: вт | D115: Пишем незнакомцу #этикет #правилаэтикета #деловоеобщение #деловойэтикет #деловаярепутация #деловыепереговоры #деловаяпереписка | E115: ссылка | F115: 143201 | G115: 37279 | H115: 37276 | I115: 15 | J115: 368 | K115: 14 | L115: 43 | M115: =IFERROR(G115/F115,"") -> 0.26032639 | N115: =IFERROR(H115/G115,"") -> 0.99991953 | O115: =IFERROR(I115/H115,"") -> 0.00040240369 | P115: =IFERROR(J115/H115,"") -> 0.0098723039 | Q115: =IFERROR(K115/H115,"") -> 0.00037557678 | R115: =IFERROR(L115/H115,"") -> 0.0011535572 | S115: =IFERROR(M115/MEDIAN(INDEX($M$5:$M$665,MATCH($A115-90,$A$5:$A$665,1)):INDEX($M$5:$M$665,MATCH($A115+90,$A$5:$A$665,1))),"") | T115: =IFERROR(N115/MEDIAN(INDEX($N$5:$N$665,MATCH($A115-90,$A$5:$A$665,1)):INDEX($N$5:$N$665,MATCH($A115+90,$A$5:$A$665,1))),"") | U115: =IFERROR(Q115/MEDIAN(INDEX($Q$5:$Q$665,MATCH($A115-90,$A$5:$A$665,1)):INDEX($Q$5:$Q$665,MATCH($A115+90,$A$5:$A$665,1))),"")
A116: 45042.5 | B116: 12 | C116: ср | D116: Заботливый хозяин | E116: ссылка | F116: 156049 | G116: 24401 | H116: 24396 | I116: 2 | J116: 260 | K116: 35 | L116: 15 | M116: =IFERROR(G116/F116,"") -> 0.15636755 | N116: =IFERROR(H116/G116,"") -> 0.99979509 | O116: =IFERROR(I116/H116,"") -> 8.1980653e-05 | P116: =IFERROR(J116/H116,"") -> 0.010657485 | Q116: =IFERROR(K116/H116,"") -> 0.0014346614 | R116: =IFERROR(L116/H116,"") -> 0.00061485489 | S116: =IFERROR(M116/MEDIAN(INDEX($M$5:$M$665,MATCH($A116-90,$A$5:$A$665,1)):INDEX($M$5:$M$665,MATCH($A116+90,$A$5:$A$665,1))),"") | T116: =IFERROR(N116/MEDIAN(INDEX($N$5:$N$665,MATCH($A116-90,$A$5:$A$665,1)):INDEX($N$5:$N$665,MATCH($A116+90,$A$5:$A$665,1))),"") | U116: =IFERROR(Q116/MEDIAN(INDEX($Q$5:$Q$665,MATCH($A116-90,$A$5:$A$665,1)):INDEX($Q$5:$Q$665,MATCH($A116+90,$A$5:$A$665,1))),"")
A117: 45043.479 | B117: 11 | C117: чт | D117: Проверьте ваши знания #этикет #правилаэтикета #этикетобщения #деловойэтикет #деловаярепутация #деловойимидж #деловыепереговоры #деловоеобщение #деловыеотношения | E117: ссылка | F117: 6309 | G117: 3059 | H117: 3067 | I117: 25 | J117: 214 | K117: 20 | L117: 11 | M117: =IFERROR(G117/F117,"") -> 0.48486289 | N117: =IFERROR(H117/G117,"") -> 1.0026152 | O117: =IFERROR(I117/H117,"") -> 0.0081512879 | P117: =IFERROR(J117/H117,"") -> 0.069775024 | Q117: =IFERROR(K117/H117,"") -> 0.0065210303 | R117: =IFERROR(L117/H117,"") -> 0.0035865667 | S117: =IFERROR(M117/MEDIAN(INDEX($M$5:$M$665,MATCH($A117-90,$A$5:$A$665,1)):INDEX($M$5:$M$665,MATCH($A117+90,$A$5:$A$665,1))),"") | T117: =IFERROR(N117/MEDIAN(INDEX($N$5:$N$665,MATCH($A117-90,$A$5:$A$665,1)):INDEX($N$5:$N$665,MATCH($A117+90,$A$5:$A$665,1))),"") | U117: =IFERROR(Q117/MEDIAN(INDEX($Q$5:$Q$665,MATCH($A117-90,$A$5:$A$665,1)):INDEX($Q$5:$Q$665,MATCH($A117+90,$A$5:$A$665,1))),"")
A118: 45044.512 | B118: 12 | C118: пт | D118: Комплимент или скандал? #этикет #правилаэтикета #этикетобщения #деловаярепутация #деловойэтикет #комплимент #комплименты #деловоеобщение #деловыеотношения | E118: ссылка | F118: 306072 | G118: 37373 | H118: 37381 | I118: 32 | J118: 343 | K118: 19 | L118: 24 | M118: =IFERROR(G118/F118,"") -> 0.12210526 | N118: =IFERROR(H118/G118,"") -> 1.0002141 | O118: =IFERROR(I118/H118,"") -> 0.00085604986 | P118: =IFERROR(J118/H118,"") -> 0.0091757845 | Q118: =IFERROR(K118/H118,"") -> 0.00050827961 | R118: =IFERROR(L118/H118,"") -> 0.0006420374 | S118: =IFERROR(M118/MEDIAN(INDEX($M$5:$M$665,MATCH($A118-90,$A$5:$A$665,1)):INDEX($M$5:$M$665,MATCH($A118+90,$A$5:$A$665,1))),"") | T118: =IFERROR(N118/MEDIAN(INDEX($N$5:$N$665,MATCH($A118-90,$A$5:$A$665,1)):INDEX($N$5:$N$665,MATCH($A118+90,$A$5:$A$665,1))),"") | U118: =IFERROR(Q118/MEDIAN(INDEX($Q$5:$Q$665,MATCH($A118-90,$A$5:$A$665,1)):INDEX($Q$5:$Q$665,MATCH($A118+90,$A$5:$A$665,1))),"")
A119: 45045.518 | B119: 12 | C119: сб | D119: Вещь взаймы | E119: ссылка | F119: 34297 | G119: 11225 | H119: 11223 | I119: 2 | J119: 317 | K119: 40 | L119: 7 | M119: =IFERROR(G119/F119,"") -> 0.3272881 | N119: =IFERROR(H119/G119,"") -> 0.99982183 | O119: =IFERROR(I119/H119,"") -> 0.00017820547 | P119: =IFERROR(J119/H119,"") -> 0.028245567 | Q119: =IFERROR(K119/H119,"") -> 0.0035641094 | R119: =IFERROR(L119/H119,"") -> 0.00062371915 | S119: =IFERROR(M119/MEDIAN(INDEX($M$5:$M$665,MATCH($A119-90,$A$5:$A$665,1)):INDEX($M$5:$M$665,MATCH($A119+90,$A$5:$A$665,1))),"") | T119: =IFERROR(N119/MEDIAN(INDEX($N$5:$N$665,MATCH($A119-90,$A$5:$A$665,1)):INDEX($N$5:$N$665,MATCH($A119+90,$A$5:$A$665,1))),"") | U119: =IFERROR(Q119/MEDIAN(INDEX($Q$5:$Q$665,MATCH($A119-90,$A$5:$A$665,1)):INDEX($Q$5:$Q$665,MATCH($A119+90,$A$5:$A$665,1))),"")
A120: 45046.586 | B120: 14 | C120: вс | D120: Этикет на даче | E120: ссылка | F120: 446231 | G120: 55146 | H120: 55140 | I120: 3 | J120: 286 | K120: 22 | L120: 14 | M120: =IFERROR(G120/F120,"") -> 0.12358173 | N120: =IFERROR(H120/G120,"") -> 0.9998912 | O120: =IFERROR(I120/H120,"") -> 5.4406964e-05 | P120: =IFERROR(J120/H120,"") -> 0.0051867972 | Q120: =IFERROR(K120/H120,"") -> 0.0003989844 | R120: =IFERROR(L120/H120,"") -> 0.00025389917 | S120: =IFERROR(M120/MEDIAN(INDEX($M$5:$M$665,MATCH($A120-90,$A$5:$A$665,1)):INDEX($M$5:$M$665,MATCH($A120+90,$A$5:$A$665,1))),"") | T120: =IFERROR(N120/MEDIAN(INDEX($N$5:$N$665,MATCH($A120-90,$A$5:$A$665,1)):INDEX($N$5:$N$665,MATCH($A120+90,$A$5:$A$665,1))),"") | U120: =IFERROR(Q120/MEDIAN(INDEX($Q$5:$Q$665,MATCH($A120-90,$A$5:$A$665,1)):INDEX($Q$5:$Q$665,MATCH($A120+90,$A$5:$A$665,1))),"")
A121: 45047.883 | B121: 21 | C121: пн | E121: ссылка | F121: 16921 | G121: 7134 | H121: 7130 | I121: 0 | J121: 221 | K121: 8 | L121: 3 | M121: =IFERROR(G121/F121,"") -> 0.42160629 | N121: =IFERROR(H121/G121,"") -> 0.9994393 | O121: =IFERROR(I121/H121,"") -> 0 | P121: =IFERROR(J121/H121,"") -> 0.030995792 | Q121: =IFERROR(K121/H121,"") -> 0.0011220196 | R121: =IFERROR(L121/H121,"") -> 0.00042075736 | S121: =IFERROR(M121/MEDIAN(INDEX($M$5:$M$665,MATCH($A121-90,$A$5:$A$665,1)):INDEX($M$5:$M$665,MATCH($A121+90,$A$5:$A$665,1))),"") | T121: =IFERROR(N121/MEDIAN(INDEX($N$5:$N$665,MATCH($A121-90,$A$5:$A$665,1)):INDEX($N$5:$N$665,MATCH($A121+90,$A$5:$A$665,1))),"") | U121: =IFERROR(Q121/MEDIAN(INDEX($Q$5:$Q$665,MATCH($A121-90,$A$5:$A$665,1)):INDEX($Q$5:$Q$665,MATCH($A121+90,$A$5:$A$665,1))),"")
A122: 45048.606 | B122: 14 | C122: вт | E122: ссылка | F122: 163355 | G122: 23922 | H122: 23919 | I122: 1 | J122: 278 | K122: 25 | L122: 11 | M122: =IFERROR(G122/F122,"") -> 0.1464418 | N122: =IFERROR(H122/G122,"") -> 0.99987459 | O122: =IFERROR(I122/H122,"") -> 4.1807768e-05 | P122: =IFERROR(J122/H122,"") -> 0.011622559 | Q122: =IFERROR(K122/H122,"") -> 0.0010451942 | R122: =IFERROR(L122/H122,"") -> 0.00045988545 | S122: =IFERROR(M122/MEDIAN(INDEX($M$5:$M$665,MATCH($A122-90,$A$5:$A$665,1)):INDEX($M$5:$M$665,MATCH($A122+90,$A$5:$A$665,1))),"") | T122: =IFERROR(N122/MEDIAN(INDEX($N$5:$N$665,MATCH($A122-90,$A$5:$A$665,1)):INDEX($N$5:$N$665,MATCH($A122+90,$A$5:$A$665,1))),"") | U122: =IFERROR(Q122/MEDIAN(INDEX($Q$5:$Q$665,MATCH($A122-90,$A$5:$A$665,1)):INDEX($Q$5:$Q$665,MATCH($A122+90,$A$5:$A$665,1))),"")
A123: 45049.818 | B123: 19 | C123: ср | E123: ссылка | F123: 100142 | G123: 27128 | H123: 27129 | I123: 3 | J123: 382 | K123: 13 | L123: 28 | M123: =IFERROR(G123/F123,"") -> 0.27089533 | N123: =IFERROR(H123/G123,"") -> 1.0000369 | O123: =IFERROR(I123/H123,"") -> 0.00011058277 | P123: =IFERROR(J123/H123,"") -> 0.014080873 | Q123: =IFERROR(K123/H123,"") -> 0.00047919201 | R123: =IFERROR(L123/H123,"") -> 0.0010321059 | S123: =IFERROR(M123/MEDIAN(INDEX($M$5:$M$665,MATCH($A123-90,$A$5:$A$665,1)):INDEX($M$5:$M$665,MATCH($A123+90,$A$5:$A$665,1))),"") | T123: =IFERROR(N123/MEDIAN(INDEX($N$5:$N$665,MATCH($A123-90,$A$5:$A$665,1)):INDEX($N$5:$N$665,MATCH($A123+90,$A$5:$A$665,1))),"") | U123: =IFERROR(Q123/MEDIAN(INDEX($Q$5:$Q$665,MATCH($A123-90,$A$5:$A$665,1)):INDEX($Q$5:$Q$665,MATCH($A123+90,$A$5:$A$665,1))),"")
A124: 45050.891 | B124: 21 | C124: чт | D124: Проверьте ваши знания 😌 | E124: ссылка | F124: 5249 | G124: 2061 | H124: 2068 | I124: 25 | J124: 142 | K124: 14 | L124: 5 | M124: =IFERROR(G124/F124,"") -> 0.39264622 | N124: =IFERROR(H124/G124,"") -> 1.0033964 | O124: =IFERROR(I124/H124,"") -> 0.012088975 | P124: =IFERROR(J124/H124,"") -> 0.068665377 | Q124: =IFERROR(K124/H124,"") -> 0.0067698259 | R124: =IFERROR(L124/H124,"") -> 0.002417795 | S124: =IFERROR(M124/MEDIAN(INDEX($M$5:$M$665,MATCH($A124-90,$A$5:$A$665,1)):INDEX($M$5:$M$665,MATCH($A124+90,$A$5:$A$665,1))),"") -> 0.98368646 | T124: =IFERROR(N124/MEDIAN(INDEX($N$5:$N$665,MATCH($A124-90,$A$5:$A$665,1)):INDEX($N$5:$N$665,MATCH($A124+90,$A$5:$A$665,1))),"") -> 1.0035503 | U124: =IFERROR(Q124/MEDIAN(INDEX($Q$5:$Q$665,MATCH($A124-90,$A$5:$A$665,1)):INDEX($Q$5:$Q$665,MATCH($A124+90,$A$5:$A$665,1))),"") -> 5.5508732
A125: 45051.584 | B125: 14 | C125: пт | D125: В поезде дальнего следования | E125: ссылка | F125: 362102 | G125: 58072 | H125: 58068 | I125: 2 | J125: 333 | K125: 27 | L125: 34 | M125: =IFERROR(G125/F125,"") -> 0.1603747 | N125: =IFERROR(H125/G125,"") -> 0.99993112 | O125: =IFERROR(I125/H125,"") -> 3.4442378e-05 | P125: =IFERROR(J125/H125,"") -> 0.0057346559 | Q125: =IFERROR(K125/H125,"") -> 0.0004649721 | R125: =IFERROR(L125/H125,"") -> 0.00058552042 | S125: =IFERROR(M125/MEDIAN(INDEX($M$5:$M$665,MATCH($A125-90,$A$5:$A$665,1)):INDEX($M$5:$M$665,MATCH($A125+90,$A$5:$A$665,1))),"") -> 0.40322815 | T125: =IFERROR(N125/MEDIAN(INDEX($N$5:$N$665,MATCH($A125-90,$A$5:$A$665,1)):INDEX($N$5:$N$665,MATCH($A125+90,$A$5:$A$665,1))),"") -> 1.0000846 | U125: =IFERROR(Q125/MEDIAN(INDEX($Q$5:$Q$665,MATCH($A125-90,$A$5:$A$665,1)):INDEX($Q$5:$Q$665,MATCH($A125+90,$A$5:$A$665,1))),"") -> 0.38016119
A126: 45052.912 | B126: 21 | C126: сб | D126: Шведский стол | E126: ссылка | F126: 27768 | G126: 14833 | H126: 14833 | I126: 43 | J126: 347 | K126: 16 | L126: 17 | M126: =IFERROR(G126/F126,"") -> 0.53417603 | N126: =IFERROR(H126/G126,"") -> 1 | O126: =IFERROR(I126/H126,"") -> 0.0028989415 | P126: =IFERROR(J126/H126,"") -> 0.023393784 | Q126: =IFERROR(K126/H126,"") -> 0.0010786759 | R126: =IFERROR(L126/H126,"") -> 0.0011460932 | S126: =IFERROR(M126/MEDIAN(INDEX($M$5:$M$665,MATCH($A126-90,$A$5:$A$665,1)):INDEX($M$5:$M$665,MATCH($A126+90,$A$5:$A$665,1))),"") -> 1.3627799 | T126: =IFERROR(N126/MEDIAN(INDEX($N$5:$N$665,MATCH($A126-90,$A$5:$A$665,1)):INDEX($N$5:$N$665,MATCH($A126+90,$A$5:$A$665,1))),"") -> 1.0001601 | U126: =IFERROR(Q126/MEDIAN(INDEX($Q$5:$Q$665,MATCH($A126-90,$A$5:$A$665,1)):INDEX($Q$5:$Q$665,MATCH($A126+90,$A$5:$A$665,1))),"") -> 0.89764806
A127: 45053.5 | B127: 12 | C127: вс | D127: Дворовый этикет | E127: ссылка | F127: 135385 | G127: 19573 | H127: 19570 | I127: 1 | J127: 185 | K127: 12 | L127: 13 | M127: =IFERROR(G127/F127,"") -> 0.14457288 | N127: =IFERROR(H127/G127,"") -> 0.99984673 | O127: =IFERROR(I127/H127,"") -> 5.109862e-05 | P127: =IFERROR(J127/H127,"") -> 0.0094532448 | Q127: =IFERROR(K127/H127,"") -> 0.00061318344 | R127: =IFERROR(L127/H127,"") -> 0.00066428206 | S127: =IFERROR(M127/MEDIAN(INDEX($M$5:$M$665,MATCH($A127-90,$A$5:$A$665,1)):INDEX($M$5:$M$665,MATCH($A127+90,$A$5:$A$665,1))),"") -> 0.36820139 | T127: =IFERROR(N127/MEDIAN(INDEX($N$5:$N$665,MATCH($A127-90,$A$5:$A$665,1)):INDEX($N$5:$N$665,MATCH($A127+90,$A$5:$A$665,1))),"") -> 1.0000062 | U127: =IFERROR(Q127/MEDIAN(INDEX($Q$5:$Q$665,MATCH($A127-90,$A$5:$A$665,1)):INDEX($Q$5:$Q$665,MATCH($A127+90,$A$5:$A$665,1))),"") -> 0.50965764
A128: 45054.525 | B128: 12 | C128: пн | D128: Комментарии #этикет #правилаэтикета | E128: ссылка | F128: 83080 | G128: 21041 | H128: 21042 | I128: 16 | J128: 328 | K128: 49 | L128: 21 | M128: =IFERROR(G128/F128,"") -> 0.25326192 | N128: =IFERROR(H128/G128,"") -> 1.0000475 | O128: =IFERROR(I128/H128,"") -> 0.00076038399 | P128: =IFERROR(J128/H128,"") -> 0.015587872 | Q128: =IFERROR(K128/H128,"") -> 0.002328676 | R128: =IFERROR(L128/H128,"") -> 0.00099800399 | S128: =IFERROR(M128/MEDIAN(INDEX($M$5:$M$665,MATCH($A128-90,$A$5:$A$665,1)):INDEX($M$5:$M$665,MATCH($A128+90,$A$5:$A$665,1))),"") -> 0.64086669 | T128: =IFERROR(N128/MEDIAN(INDEX($N$5:$N$665,MATCH($A128-90,$A$5:$A$665,1)):INDEX($N$5:$N$665,MATCH($A128+90,$A$5:$A$665,1))),"") -> 1.0002076 | U128: =IFERROR(Q128/MEDIAN(INDEX($Q$5:$Q$665,MATCH($A128-90,$A$5:$A$665,1)):INDEX($Q$5:$Q$665,MATCH($A128+90,$A$5:$A$665,1))),"") -> 1.9251387
A129: 45056.58 | B129: 13 | C129: ср | D129: Шумная компания | E129: ссылка | F129: 70812 | G129: 11527 | H129: 11522 | I129: 1 | J129: 225 | K129: 19 | L129: 14 | M129: =IFERROR(G129/F129,"") -> 0.16278314 | N129: =IFERROR(H129/G129,"") -> 0.99956624 | O129: =IFERROR(I129/H129,"") -> 8.6790488e-05 | P129: =IFERROR(J129/H129,"") -> 0.01952786 | Q129: =IFERROR(K129/H129,"") -> 0.0016490193 | R129: =IFERROR(L129/H129,"") -> 0.0012150668 | S129: =IFERROR(M129/MEDIAN(INDEX($M$5:$M$665,MATCH($A129-90,$A$5:$A$665,1)):INDEX($M$5:$M$665,MATCH($A129+90,$A$5:$A$665,1))),"") -> 0.41766387 | T129: =IFERROR(N129/MEDIAN(INDEX($N$5:$N$665,MATCH($A129-90,$A$5:$A$665,1)):INDEX($N$5:$N$665,MATCH($A129+90,$A$5:$A$665,1))),"") -> 0.99972623 | U129: =IFERROR(Q129/MEDIAN(INDEX($Q$5:$Q$665,MATCH($A129-90,$A$5:$A$665,1)):INDEX($Q$5:$Q$665,MATCH($A129+90,$A$5:$A$665,1))),"") -> 1.375255
A130: 45057.585 | B130: 14 | C130: чт | D130: Головной убор в ресторане | E130: ссылка | F130: 46658 | G130: 12314 | H130: 12310 | I130: 56 | J130: 242 | K130: 21 | L130: 9 | M130: =IFERROR(G130/F130,"") -> 0.26392044 | N130: =IFERROR(H130/G130,"") -> 0.99967517 | O130: =IFERROR(I130/H130,"") -> 0.004549147 | P130: =IFERROR(J130/H130,"") -> 0.019658814 | Q130: =IFERROR(K130/H130,"") -> 0.0017059301 | R130: =IFERROR(L130/H130,"") -> 0.00073111292 | S130: =IFERROR(M130/MEDIAN(INDEX($M$5:$M$665,MATCH($A130-90,$A$5:$A$665,1)):INDEX($M$5:$M$665,MATCH($A130+90,$A$5:$A$665,1))),"") -> 0.6831266 | T130: =IFERROR(N130/MEDIAN(INDEX($N$5:$N$665,MATCH($A130-90,$A$5:$A$665,1)):INDEX($N$5:$N$665,MATCH($A130+90,$A$5:$A$665,1))),"") -> 0.99983603 | U130: =IFERROR(Q130/MEDIAN(INDEX($Q$5:$Q$665,MATCH($A130-90,$A$5:$A$665,1)):INDEX($Q$5:$Q$665,MATCH($A130+90,$A$5:$A$665,1))),"") -> 1.4227178
A131: 45058.573 | B131: 13 | C131: пт | D131: Время проверить свои знания 🙌🏻 | E131: ссылка | F131: 6284 | G131: 2595 | H131: 2601 | I131: 32 | J131: 182 | K131: 12 | L131: 2 | M131: =IFERROR(G131/F131,"") -> 0.41295353 | N131: =IFERROR(H131/G131,"") -> 1.0023121 | O131: =IFERROR(I131/H131,"") -> 0.01230296 | P131: =IFERROR(J131/H131,"") -> 0.069973087 | Q131: =IFERROR(K131/H131,"") -> 0.0046136101 | R131: =IFERROR(L131/H131,"") -> 0.00076893502 | S131: =IFERROR(M131/MEDIAN(INDEX($M$5:$M$665,MATCH($A131-90,$A$5:$A$665,1)):INDEX($M$5:$M$665,MATCH($A131+90,$A$5:$A$665,1))),"") -> 1.068881 | T131: =IFERROR(N131/MEDIAN(INDEX($N$5:$N$665,MATCH($A131-90,$A$5:$A$665,1)):INDEX($N$5:$N$665,MATCH($A131+90,$A$5:$A$665,1))),"") -> 1.0024726 | U131: =IFERROR(Q131/MEDIAN(INDEX($Q$5:$Q$665,MATCH($A131-90,$A$5:$A$665,1)):INDEX($Q$5:$Q$665,MATCH($A131+90,$A$5:$A$665,1))),"") -> 3.8031258
A132: 45059.552 | B132: 13 | C132: сб | D132: Пляжный отдых | E132: ссылка | F132: 126220 | G132: 26221 | H132: 26216 | I132: 7 | J132: 323 | K132: 18 | L132: 36 | M132: =IFERROR(G132/F132,"") -> 0.20774045 | N132: =IFERROR(H132/G132,"") -> 0.99980931 | O132: =IFERROR(I132/H132,"") -> 0.00026701251 | P132: =IFERROR(J132/H132,"") -> 0.01232072 | Q132: =IFERROR(K132/H132,"") -> 0.0006866036 | R132: =IFERROR(L132/H132,"") -> 0.0013732072 | S132: =IFERROR(M132/MEDIAN(INDEX($M$5:$M$665,MATCH($A132-90,$A$5:$A$665,1)):INDEX($M$5:$M$665,MATCH($A132+90,$A$5:$A$665,1))),"") -> 0.54087354 | T132: =IFERROR(N132/MEDIAN(INDEX($N$5:$N$665,MATCH($A132-90,$A$5:$A$665,1)):INDEX($N$5:$N$665,MATCH($A132+90,$A$5:$A$665,1))),"") -> 0.99996279 | U132: =IFERROR(Q132/MEDIAN(INDEX($Q$5:$Q$665,MATCH($A132-90,$A$5:$A$665,1)):INDEX($Q$5:$Q$665,MATCH($A132+90,$A$5:$A$665,1))),"") -> 0.5613671
A133: 45060.501 | B133: 12 | C133: вс | D133: Место в поезде | E133: ссылка | F133: 14707 | G133: 6310 | H133: 6303 | I133: 12 | J133: 264 | K133: 11 | L133: 4 | M133: =IFERROR(G133/F133,"") -> 0.42904739 | N133: =IFERROR(H133/G133,"") -> 0.99889065 | O133: =IFERROR(I133/H133,"") -> 0.0019038553 | P133: =IFERROR(J133/H133,"") -> 0.041884817 | Q133: =IFERROR(K133/H133,"") -> 0.0017452007 | R133: =IFERROR(L133/H133,"") -> 0.00063461844 | S133: =IFERROR(M133/MEDIAN(INDEX($M$5:$M$665,MATCH($A133-90,$A$5:$A$665,1)):INDEX($M$5:$M$665,MATCH($A133+90,$A$5:$A$665,1))),"") -> 1.1286182 | T133: =IFERROR(N133/MEDIAN(INDEX($N$5:$N$665,MATCH($A133-90,$A$5:$A$665,1)):INDEX($N$5:$N$665,MATCH($A133+90,$A$5:$A$665,1))),"") -> 0.99904998 | U133: =IFERROR(Q133/MEDIAN(INDEX($Q$5:$Q$665,MATCH($A133-90,$A$5:$A$665,1)):INDEX($Q$5:$Q$665,MATCH($A133+90,$A$5:$A$665,1))),"") -> 1.4268761
...

Sheet Посты
A1: Посты
A2: Короткие посты. Отдельный лист по той же причине.
A4: Дата публикации | B4: Час | C4: День недели | D4: Заголовок | E4: Ссылка | F4: Показы | G4: Открытия | H4: Дочитывания | I4: Время просмотра, мин | J4: Лайки | K4: Комментарии | L4: Подписки | M4: CTR (открытия/показы) | N4: Дочитываемость | O4: Минут на дочитывание | P4: Лайки / дочитывания | Q4: Комментарии / дочитывания | R4: Подписки / дочитывания | S4: Индекс CTR к периоду | T4: Индекс дочитываемости к периоду | U4: Индекс комментариев к периоду
A5: 44977.689 | B5: 16 | C5: пн | D5: Мастер-класс по имиджу и деловому этикету Если у вас нет планов на 6 марта и… | E5: ссылка | F5: 1059 | G5: 157 | H5: 153 | I5: 8 | J5: 6 | K5: 0 | L5: 0 | M5: =IFERROR(G5/F5,"") -> 0.14825307 | N5: =IFERROR(H5/G5,"") -> 0.97452229 | O5: =IFERROR(I5/H5,"") -> 0.052287582 | P5: =IFERROR(J5/H5,"") -> 0.039215686 | Q5: =IFERROR(K5/H5,"") -> 0 | R5: =IFERROR(L5/H5,"") -> 0 | S5: =IFERROR(M5/MEDIAN(INDEX($M$5:$M$373,MATCH($A5-90,$A$5:$A$373,1)):INDEX($M$5:$M$373,MATCH($A5+90,$A$5:$A$373,1))),"") | T5: =IFERROR(N5/MEDIAN(INDEX($N$5:$N$373,MATCH($A5-90,$A$5:$A$373,1)):INDEX($N$5:$N$373,MATCH($A5+90,$A$5:$A$373,1))),"") | U5: =IFERROR(Q5/MEDIAN(INDEX($Q$5:$Q$373,MATCH($A5-90,$A$5:$A$373,1)):INDEX($Q$5:$Q$373,MATCH($A5+90,$A$5:$A$373,1))),"")
A6: 44979.602 | B6: 14 | C6: ср | D6: Много не бывает! Образований.. Я заканчиваю школу и нервно думаю, куда… | E6: ссылка | F6: 1234 | G6: 367 | H6: 366 | I6: 24 | J6: 17 | K6: 0 | L6: 1 | M6: =IFERROR(G6/F6,"") -> 0.29740681 | N6: =IFERROR(H6/G6,"") -> 0.9972752 | O6: =IFERROR(I6/H6,"") -> 0.06557377 | P6: =IFERROR(J6/H6,"") -> 0.046448087 | Q6: =IFERROR(K6/H6,"") -> 0 | R6: =IFERROR(L6/H6,"") -> 0.0027322404 | S6: =IFERROR(M6/MEDIAN(INDEX($M$5:$M$373,MATCH($A6-90,$A$5:$A$373,1)):INDEX($M$5:$M$373,MATCH($A6+90,$A$5:$A$373,1))),"") | T6: =IFERROR(N6/MEDIAN(INDEX($N$5:$N$373,MATCH($A6-90,$A$5:$A$373,1)):INDEX($N$5:$N$373,MATCH($A6+90,$A$5:$A$373,1))),"") | U6: =IFERROR(Q6/MEDIAN(INDEX($Q$5:$Q$373,MATCH($A6-90,$A$5:$A$373,1)):INDEX($Q$5:$Q$373,MATCH($A6+90,$A$5:$A$373,1))),"")
A7: 44993.851 | B7: 20 | C7: ср | D7: Накануне Международного женского дня прошла конференция «Женщины ДЕЛА… | E7: ссылка | F7: 2405 | G7: 397 | H7: 396 | I7: 1 | J7: 19 | K7: 2 | L7: 2 | M7: =IFERROR(G7/F7,"") -> 0.16507277 | N7: =IFERROR(H7/G7,"") -> 0.99748111 | O7: =IFERROR(I7/H7,"") -> 0.0025252525 | P7: =IFERROR(J7/H7,"") -> 0.047979798 | Q7: =IFERROR(K7/H7,"") -> 0.0050505051 | R7: =IFERROR(L7/H7,"") -> 0.0050505051 | S7: =IFERROR(M7/MEDIAN(INDEX($M$5:$M$373,MATCH($A7-90,$A$5:$A$373,1)):INDEX($M$5:$M$373,MATCH($A7+90,$A$5:$A$373,1))),"") | T7: =IFERROR(N7/MEDIAN(INDEX($N$5:$N$373,MATCH($A7-90,$A$5:$A$373,1)):INDEX($N$5:$N$373,MATCH($A7+90,$A$5:$A$373,1))),"") | U7: =IFERROR(Q7/MEDIAN(INDEX($Q$5:$Q$373,MATCH($A7-90,$A$5:$A$373,1)):INDEX($Q$5:$Q$373,MATCH($A7+90,$A$5:$A$373,1))),"")
A8: 45006.447 | B8: 10 | C8: вт | D8: Новости по социальному проекту Я очень рада поделиться новостями о социальном… | E8: ссылка | F8: 5493 | G8: 663 | H8: 659 | I8: 29 | J8: 42 | K8: 4 | L8: 2 | M8: =IFERROR(G8/F8,"") -> 0.12069907 | N8: =IFERROR(H8/G8,"") -> 0.99396682 | O8: =IFERROR(I8/H8,"") -> 0.04400607 | P8: =IFERROR(J8/H8,"") -> 0.063732929 | Q8: =IFERROR(K8/H8,"") -> 0.0060698027 | R8: =IFERROR(L8/H8,"") -> 0.0030349014 | S8: =IFERROR(M8/MEDIAN(INDEX($M$5:$M$373,MATCH($A8-90,$A$5:$A$373,1)):INDEX($M$5:$M$373,MATCH($A8+90,$A$5:$A$373,1))),"") | T8: =IFERROR(N8/MEDIAN(INDEX($N$5:$N$373,MATCH($A8-90,$A$5:$A$373,1)):INDEX($N$5:$N$373,MATCH($A8+90,$A$5:$A$373,1))),"") | U8: =IFERROR(Q8/MEDIAN(INDEX($Q$5:$Q$373,MATCH($A8-90,$A$5:$A$373,1)):INDEX($Q$5:$Q$373,MATCH($A8+90,$A$5:$A$373,1))),"")
A9: 45010.019 | B9: 0 | C9: сб | D9: Пару дней назад посетила очередную школу со своим проектом «Образ Будущего… | E9: ссылка | F9: 13661 | G9: 1899 | H9: 1896 | I9: 16 | J9: 65 | K9: 11 | L9: 0 | M9: =IFERROR(G9/F9,"") -> 0.13900886 | N9: =IFERROR(H9/G9,"") -> 0.99842022 | O9: =IFERROR(I9/H9,"") -> 0.0084388186 | P9: =IFERROR(J9/H9,"") -> 0.0342827 | Q9: =IFERROR(K9/H9,"") -> 0.0058016878 | R9: =IFERROR(L9/H9,"") -> 0 | S9: =IFERROR(M9/MEDIAN(INDEX($M$5:$M$373,MATCH($A9-90,$A$5:$A$373,1)):INDEX($M$5:$M$373,MATCH($A9+90,$A$5:$A$373,1))),"") | T9: =IFERROR(N9/MEDIAN(INDEX($N$5:$N$373,MATCH($A9-90,$A$5:$A$373,1)):INDEX($N$5:$N$373,MATCH($A9+90,$A$5:$A$373,1))),"") | U9: =IFERROR(Q9/MEDIAN(INDEX($Q$5:$Q$373,MATCH($A9-90,$A$5:$A$373,1)):INDEX($Q$5:$Q$373,MATCH($A9+90,$A$5:$A$373,1))),"")
A10: 45036.262 | B10: 6 | C10: чт | D10: НЕ всегда говори да Многие из нас боятся сказать "нет". Мы переживаем, что… | E10: ссылка | F10: 7280 | G10: 1211 | H10: 1210 | I10: 5 | J10: 32 | K10: 3 | L10: 7 | M10: =IFERROR(G10/F10,"") -> 0.16634615 | N10: =IFERROR(H10/G10,"") -> 0.99917424 | O10: =IFERROR(I10/H10,"") -> 0.0041322314 | P10: =IFERROR(J10/H10,"") -> 0.026446281 | Q10: =IFERROR(K10/H10,"") -> 0.0024793388 | R10: =IFERROR(L10/H10,"") -> 0.005785124 | S10: =IFERROR(M10/MEDIAN(INDEX($M$5:$M$373,MATCH($A10-90,$A$5:$A$373,1)):INDEX($M$5:$M$373,MATCH($A10+90,$A$5:$A$373,1))),"") | T10: =IFERROR(N10/MEDIAN(INDEX($N$5:$N$373,MATCH($A10-90,$A$5:$A$373,1)):INDEX($N$5:$N$373,MATCH($A10+90,$A$5:$A$373,1))),"") | U10: =IFERROR(Q10/MEDIAN(INDEX($Q$5:$Q$373,MATCH($A10-90,$A$5:$A$373,1)):INDEX($Q$5:$Q$373,MATCH($A10+90,$A$5:$A$373,1))),"")
A11: 45037.43 | B11: 10 | C11: пт | D11: Воскресенье - прекрасный день, Чтобы посетить петербургскую ярмарку 💫 Я не… | E11: ссылка | F11: 3457 | G11: 313 | H11: 312 | I11: 2 | J11: 16 | K11: 2 | L11: 0 | M11: =IFERROR(G11/F11,"") -> 0.090540931 | N11: =IFERROR(H11/G11,"") -> 0.99680511 | O11: =IFERROR(I11/H11,"") -> 0.0064102564 | P11: =IFERROR(J11/H11,"") -> 0.051282051 | Q11: =IFERROR(K11/H11,"") -> 0.0064102564 | R11: =IFERROR(L11/H11,"") -> 0 | S11: =IFERROR(M11/MEDIAN(INDEX($M$5:$M$373,MATCH($A11-90,$A$5:$A$373,1)):INDEX($M$5:$M$373,MATCH($A11+90,$A$5:$A$373,1))),"") | T11: =IFERROR(N11/MEDIAN(INDEX($N$5:$N$373,MATCH($A11-90,$A$5:$A$373,1)):INDEX($N$5:$N$373,MATCH($A11+90,$A$5:$A$373,1))),"") | U11: =IFERROR(Q11/MEDIAN(INDEX($Q$5:$Q$373,MATCH($A11-90,$A$5:$A$373,1)):INDEX($Q$5:$Q$373,MATCH($A11+90,$A$5:$A$373,1))),"")
A12: 45040.405 | B12: 9 | C12: пн | D12: Мистер и Мисс Этикет На днях мне прислали ссылку на хранилище с видео от… | E12: ссылка | F12: 4454 | G12: 831 | H12: 830 | I12: 1 | J12: 33 | K12: 3 | L12: 0 | M12: =IFERROR(G12/F12,"") -> 0.18657387 | N12: =IFERROR(H12/G12,"") -> 0.99879663 | O12: =IFERROR(I12/H12,"") -> 0.0012048193 | P12: =IFERROR(J12/H12,"") -> 0.039759036 | Q12: =IFERROR(K12/H12,"") -> 0.0036144578 | R12: =IFERROR(L12/H12,"") -> 0 | S12: =IFERROR(M12/MEDIAN(INDEX($M$5:$M$373,MATCH($A12-90,$A$5:$A$373,1)):INDEX($M$5:$M$373,MATCH($A12+90,$A$5:$A$373,1))),"") | T12: =IFERROR(N12/MEDIAN(INDEX($N$5:$N$373,MATCH($A12-90,$A$5:$A$373,1)):INDEX($N$5:$N$373,MATCH($A12+90,$A$5:$A$373,1))),"") | U12: =IFERROR(Q12/MEDIAN(INDEX($Q$5:$Q$373,MATCH($A12-90,$A$5:$A$373,1)):INDEX($Q$5:$Q$373,MATCH($A12+90,$A$5:$A$373,1))),"")
A13: 45051.379 | B13: 9 | C13: пт | D13: У меня красивая фигура, но зачастую я выбираю оверсайзы и мужские пиджаки… | E13: ссылка | F13: 4981 | G13: 1220 | H13: 1216 | I13: 7 | J13: 87 | K13: 8 | L13: 2 | M13: =IFERROR(G13/F13,"") -> 0.24493074 | N13: =IFERROR(H13/G13,"") -> 0.99672131 | O13: =IFERROR(I13/H13,"") -> 0.0057565789 | P13: =IFERROR(J13/H13,"") -> 0.071546053 | Q13: =IFERROR(K13/H13,"") -> 0.0065789474 | R13: =IFERROR(L13/H13,"") -> 0.0016447368 | S13: =IFERROR(M13/MEDIAN(INDEX($M$5:$M$373,MATCH($A13-90,$A$5:$A$373,1)):INDEX($M$5:$M$373,MATCH($A13+90,$A$5:$A$373,1))),"") | T13: =IFERROR(N13/MEDIAN(INDEX($N$5:$N$373,MATCH($A13-90,$A$5:$A$373,1)):INDEX($N$5:$N$373,MATCH($A13+90,$A$5:$A$373,1))),"") | U13: =IFERROR(Q13/MEDIAN(INDEX($Q$5:$Q$373,MATCH($A13-90,$A$5:$A$373,1)):INDEX($Q$5:$Q$373,MATCH($A13+90,$A$5:$A$373,1))),"")
A14: 45076.417 | B14: 10 | C14: вт | D14: Я выгорела или сгорела от обиды и непонимания, даже не знаю, что было бы… | E14: ссылка | F14: 1357 | G14: 534 | H14: 529 | I14: 29 | J14: 59 | K14: 49 | L14: 4 | M14: =IFERROR(G14/F14,"") -> 0.39351511 | N14: =IFERROR(H14/G14,"") -> 0.9906367 | O14: =IFERROR(I14/H14,"") -> 0.054820416 | P14: =IFERROR(J14/H14,"") -> 0.11153119 | Q14: =IFERROR(K14/H14,"") -> 0.092627599 | R14: =IFERROR(L14/H14,"") -> 0.0075614367 | S14: =IFERROR(M14/MEDIAN(INDEX($M$5:$M$373,MATCH($A14-90,$A$5:$A$373,1)):INDEX($M$5:$M$373,MATCH($A14+90,$A$5:$A$373,1))),"") -> 1.913824 | T14: =IFERROR(N14/MEDIAN(INDEX($N$5:$N$373,MATCH($A14-90,$A$5:$A$373,1)):INDEX($N$5:$N$373,MATCH($A14+90,$A$5:$A$373,1))),"") -> 0.99326662 | U14: =IFERROR(Q14/MEDIAN(INDEX($Q$5:$Q$373,MATCH($A14-90,$A$5:$A$373,1)):INDEX($Q$5:$Q$373,MATCH($A14+90,$A$5:$A$373,1))),"") -> 17.444646
